2024-02-06T14:01:40 {"cpu": 0.10888671875, "cpu_total": 3, "cpu_usage": 0.036295572916666664, "memory": 1186.0, "memory_total": 4011.0, "memory_usage": 0.2956868611318873, "pipeline_run_id": 1, "pipeline_schedule_id": 1, "pipeline_uuid": "green_taxi_etl", "hostname": "96649ac3d4ab", "level": "INFO", "message": "Pipeline green_taxi_etl for run 1 in schedule 1 is alive.", "timestamp": 1707228100.992141, "uuid": "60c20c63517c43f6befc154610d2b34b"}
2024-02-06T14:01:41 {"block_run_id": 1, "block_uuid": "load_green_taxi_data", "pipeline_run_id": 1, "pipeline_schedule_id": 1, "pipeline_uuid": "green_taxi_etl", "hostname": "96649ac3d4ab", "level": "INFO", "message": "Execute PipelineRun 1, BlockRun 1: pipeline green_taxi_etl block load_green_taxi_data", "timestamp": 1707228101.712675, "uuid": "64295b054b5246c4983827791f72bb07"}
2024-02-06T14:01:41 {"cpu": 0.119140625, "cpu_total": 3, "cpu_usage": 0.039713541666666664, "memory": 1271.0, "memory_total": 4011.0, "memory_usage": 0.3168785838942907, "pipeline_run_id": 1, "pipeline_schedule_id": 1, "pipeline_uuid": "green_taxi_etl", "hostname": "96649ac3d4ab", "level": "INFO", "message": "Pipeline green_taxi_etl for run 1 in schedule 1 is alive.", "timestamp": 1707228101.734849, "uuid": "61c2c35a6f1949969b1623dc4ce626d2"}
2024-02-06T14:01:42 {"block_run_id": 4, "block_uuid": "test_green_taxi_data_postgres", "pipeline_run_id": 1, "pipeline_schedule_id": 1, "pipeline_uuid": "green_taxi_etl", "hostname": "96649ac3d4ab", "level": "INFO", "message": "Execute PipelineRun 1, BlockRun 4: pipeline green_taxi_etl block test_green_taxi_data_postgres", "timestamp": 1707228102.735016, "uuid": "03fff8cc59fd466893ca31754e824658"}
2024-02-06T14:01:45 {"block_run_id": 4, "block_uuid": "test_green_taxi_data_postgres", "pipeline_run_id": 1, "pipeline_schedule_id": 1, "pipeline_uuid": "green_taxi_etl", "hostname": "96649ac3d4ab", "level": "EXCEPTION", "message": "BlockRun 4 (block_uuid: test_green_taxi_data_postgres) failed.", "timestamp": 1707228105.970499, "uuid": "95a5cffd441943039dc6983be86cc9e0", "error": ["Traceback (most recent call last):\n  File \"/usr/local/lib/python3.10/site-packages/pandas/io/sql.py\", line 2018, in execute\n    cur.execute(*args, **kwargs)\npsycopg2.errors.UndefinedTable: relation \"mage.green_taxi\" does not exist\nLINE 1: SELECT DISTINCT vendor_id FROM mage.green_taxi\n                                       ^\n\n\nThe above exception was the direct cause of the following exception:\n\nTraceback (most recent call last):\n  File \"/usr/local/lib/python3.10/site-packages/mage_ai/data_preparation/executors/block_executor.py\", line 613, in execute\n    result = __execute_with_retry()\n  File \"/usr/local/lib/python3.10/site-packages/mage_ai/shared/retry.py\", line 54, in retry_func\n    raise e\n  File \"/usr/local/lib/python3.10/site-packages/mage_ai/shared/retry.py\", line 38, in retry_func\n    return func(*args, **kwargs)\n  File \"/usr/local/lib/python3.10/site-packages/mage_ai/data_preparation/executors/block_executor.py\", line 588, in __execute_with_retry\n    return self._execute(\n  File \"/usr/local/lib/python3.10/site-packages/mage_ai/data_preparation/executors/block_executor.py\", line 1077, in _execute\n    result = self.block.execute_sync(\n  File \"/usr/local/lib/python3.10/site-packages/mage_ai/data_preparation/models/block/__init__.py\", line 1312, in execute_sync\n    raise err\n  File \"/usr/local/lib/python3.10/site-packages/mage_ai/data_preparation/models/block/__init__.py\", line 1221, in execute_sync\n    output = self.execute_block(\n  File \"/usr/local/lib/python3.10/site-packages/mage_ai/data_preparation/models/block/__init__.py\", line 1527, in execute_block\n    outputs = self._execute_block(\n  File \"/usr/local/lib/python3.10/site-packages/mage_ai/data_preparation/models/block/sql/__init__.py\", line 721, in _execute_block\n    return execute_sql_code(\n  File \"/usr/local/lib/python3.10/site-packages/mage_ai/data_preparation/models/block/sql/__init__.py\", line 457, in execute_sql_code\n    return execute_raw_sql(\n  File \"/usr/local/lib/python3.10/site-packages/mage_ai/data_preparation/models/block/sql/__init__.py\", line 694, in execute_raw_sql\n    results = loader.execute_queries(\n  File \"/usr/local/lib/python3.10/site-packages/mage_ai/io/sql.py\", line 152, in execute_queries\n    result = self.fetch_query(\n  File \"/usr/local/lib/python3.10/site-packages/mage_ai/io/sql.py\", line 167, in fetch_query\n    return read_sql(query, self.conn)\n  File \"/usr/local/lib/python3.10/site-packages/pandas/io/sql.py\", line 564, in read_sql\n    return pandas_sql.read_query(\n  File \"/usr/local/lib/python3.10/site-packages/pandas/io/sql.py\", line 2078, in read_query\n    cursor = self.execute(*args)\n  File \"/usr/local/lib/python3.10/site-packages/pandas/io/sql.py\", line 2030, in execute\n    raise ex from exc\npandas.errors.DatabaseError: Execution failed on sql 'SELECT DISTINCT vendor_id FROM mage.green_taxi': relation \"mage.green_taxi\" does not exist\nLINE 1: SELECT DISTINCT vendor_id FROM mage.green_taxi\n                                       ^\n\n"], "error_stack": [["  File \"/usr/local/bin/mage\", line 8, in <module>\n    sys.exit(app())\n", "  File \"/usr/local/lib/python3.10/site-packages/typer/main.py\", line 311, in __call__\n    return get_command(self)(*args, **kwargs)\n", "  File \"/usr/local/lib/python3.10/site-packages/click/core.py\", line 1130, in __call__\n    return self.main(*args, **kwargs)\n", "  File \"/usr/local/lib/python3.10/site-packages/typer/core.py\", line 778, in main\n    return _main(\n", "  File \"/usr/local/lib/python3.10/site-packages/typer/core.py\", line 216, in _main\n    rv = self.invoke(ctx)\n", "  File \"/usr/local/lib/python3.10/site-packages/click/core.py\", line 1657, in invoke\n    return _process_result(sub_ctx.command.invoke(sub_ctx))\n", "  File \"/usr/local/lib/python3.10/site-packages/click/core.py\", line 1404, in invoke\n    return ctx.invoke(self.callback, **ctx.params)\n", "  File \"/usr/local/lib/python3.10/site-packages/click/core.py\", line 760, in invoke\n    return __callback(*args, **kwargs)\n", "  File \"/usr/local/lib/python3.10/site-packages/typer/main.py\", line 683, in wrapper\n    return callback(**use_params)  # type: ignore\n", "  File \"/usr/local/lib/python3.10/site-packages/mage_ai/cli/main.py\", line 163, in start\n    start_server(\n", "  File \"/usr/local/lib/python3.10/site-packages/mage_ai/server/server.py\", line 659, in start_server\n    scheduler_manager.start_scheduler()\n", "  File \"/usr/local/lib/python3.10/site-packages/mage_ai/server/scheduler_manager.py\", line 87, in start_scheduler\n    proc.start()\n", "  File \"/usr/local/lib/python3.10/multiprocessing/process.py\", line 121, in start\n    self._popen = self._Popen(self)\n", "  File \"/usr/local/lib/python3.10/multiprocessing/context.py\", line 224, in _Popen\n    return _default_context.get_context().Process._Popen(process_obj)\n", "  File \"/usr/local/lib/python3.10/multiprocessing/context.py\", line 281, in _Popen\n    return Popen(process_obj)\n", "  File \"/usr/local/lib/python3.10/multiprocessing/popen_fork.py\", line 19, in __init__\n    self._launch(process_obj)\n", "  File \"/usr/local/lib/python3.10/multiprocessing/popen_fork.py\", line 71, in _launch\n    code = process_obj._bootstrap(parent_sentinel=child_r)\n", "  File \"/usr/local/lib/python3.10/multiprocessing/process.py\", line 314, in _bootstrap\n    self.run()\n", "  File \"/usr/local/lib/python3.10/multiprocessing/process.py\", line 108, in run\n    self._target(*self._args, **self._kwargs)\n", "  File \"/usr/local/lib/python3.10/site-packages/mage_ai/orchestration/db/process.py\", line 15, in start_session_and_run\n    results = target(*args)\n", "  File \"/usr/local/lib/python3.10/site-packages/mage_ai/server/scheduler_manager.py\", line 50, in run_scheduler\n    LoopTimeTrigger().start()\n", "  File \"/usr/local/lib/python3.10/site-packages/mage_ai/orchestration/triggers/loop_time_trigger.py\", line 14, in start\n    self.run()\n", "  File \"/usr/local/lib/python3.10/site-packages/mage_ai/orchestration/triggers/time_trigger.py\", line 11, in run\n    schedule_all()\n", "  File \"/usr/local/lib/python3.10/site-packages/mage_ai/orchestration/pipeline_scheduler_original.py\", line 1575, in schedule_all\n    PipelineScheduler(r).start()\n", "  File \"/usr/local/lib/python3.10/site-packages/mage_ai/orchestration/db/__init__.py\", line 149, in func_with_rollback\n    return func(*args, **kwargs)\n", "  File \"/usr/local/lib/python3.10/site-packages/mage_ai/orchestration/pipeline_scheduler_original.py\", line 182, in start\n    self.schedule()\n", "  File \"/usr/local/lib/python3.10/site-packages/mage_ai/orchestration/db/__init__.py\", line 149, in func_with_rollback\n    return func(*args, **kwargs)\n", "  File \"/usr/local/lib/python3.10/site-packages/mage_ai/orchestration/pipeline_scheduler_original.py\", line 319, in schedule\n    self.__schedule_blocks(block_runs)\n", "  File \"/usr/local/lib/python3.10/site-packages/mage_ai/orchestration/pipeline_scheduler_original.py\", line 584, in __schedule_blocks\n    job_manager.add_job(\n", "  File \"/usr/local/lib/python3.10/site-packages/mage_ai/orchestration/job_manager.py\", line 27, in add_job\n    self.queue.enqueue(job_id, target, *args, **kwargs)\n", "  File \"/usr/local/lib/python3.10/site-packages/mage_ai/orchestration/queue/process_queue.py\", line 108, in enqueue\n    self.start_worker_pool()\n", "  File \"/usr/local/lib/python3.10/site-packages/mage_ai/orchestration/queue/process_queue.py\", line 183, in start_worker_pool\n    self.worker_pool_proc.start()\n", "  File \"/usr/local/lib/python3.10/multiprocessing/process.py\", line 121, in start\n    self._popen = self._Popen(self)\n", "  File \"/usr/local/lib/python3.10/multiprocessing/context.py\", line 224, in _Popen\n    return _default_context.get_context().Process._Popen(process_obj)\n", "  File \"/usr/local/lib/python3.10/multiprocessing/context.py\", line 281, in _Popen\n    return Popen(process_obj)\n", "  File \"/usr/local/lib/python3.10/multiprocessing/popen_fork.py\", line 19, in __init__\n    self._launch(process_obj)\n", "  File \"/usr/local/lib/python3.10/multiprocessing/popen_fork.py\", line 71, in _launch\n    code = process_obj._bootstrap(parent_sentinel=child_r)\n", "  File \"/usr/local/lib/python3.10/multiprocessing/process.py\", line 314, in _bootstrap\n    self.run()\n", "  File \"/usr/local/lib/python3.10/multiprocessing/process.py\", line 108, in run\n    self._target(*self._args, **self._kwargs)\n", "  File \"/usr/local/lib/python3.10/site-packages/mage_ai/orchestration/queue/process_queue.py\", line 288, in poll_job_and_execute\n    worker.start()\n", "  File \"/usr/local/lib/python3.10/multiprocessing/process.py\", line 121, in start\n    self._popen = self._Popen(self)\n", "  File \"/usr/local/lib/python3.10/multiprocessing/context.py\", line 224, in _Popen\n    return _default_context.get_context().Process._Popen(process_obj)\n", "  File \"/usr/local/lib/python3.10/multiprocessing/context.py\", line 281, in _Popen\n    return Popen(process_obj)\n", "  File \"/usr/local/lib/python3.10/multiprocessing/popen_fork.py\", line 19, in __init__\n    self._launch(process_obj)\n", "  File \"/usr/local/lib/python3.10/multiprocessing/popen_fork.py\", line 71, in _launch\n    code = process_obj._bootstrap(parent_sentinel=child_r)\n", "  File \"/usr/local/lib/python3.10/multiprocessing/process.py\", line 314, in _bootstrap\n    self.run()\n", "  File \"/usr/local/lib/python3.10/site-packages/newrelic/api/background_task.py\", line 117, in wrapper\n    return wrapped(*args, **kwargs)\n", "  File \"/usr/local/lib/python3.10/site-packages/mage_ai/orchestration/queue/process_queue.py\", line 253, in run\n    start_session_and_run(args[1], *args[2], **args[3])\n", "  File \"/usr/local/lib/python3.10/site-packages/mage_ai/orchestration/db/process.py\", line 15, in start_session_and_run\n    results = target(*args)\n", "  File \"/usr/local/lib/python3.10/site-packages/mage_ai/orchestration/pipeline_scheduler_original.py\", line 1128, in run_block\n    return ExecutorFactory.get_block_executor(\n", "  File \"/usr/local/lib/python3.10/site-packages/mage_ai/data_preparation/executors/block_executor.py\", line 641, in execute\n    on_failure(\n", "  File \"/usr/local/lib/python3.10/site-packages/mage_ai/orchestration/db/__init__.py\", line 149, in func_with_rollback\n    return func(*args, **kwargs)\n", "  File \"/usr/local/lib/python3.10/site-packages/mage_ai/orchestration/pipeline_scheduler_original.py\", line 415, in on_block_failure\n    self.logger.exception(\n", "  File \"/usr/local/lib/python3.10/site-packages/mage_ai/data_preparation/logging/logger.py\", line 30, in exception\n    self.__send_message('exception', message, **kwargs)\n", "  File \"/usr/local/lib/python3.10/site-packages/mage_ai/data_preparation/logging/logger.py\", line 59, in __send_message\n    data['error_stack'] = traceback.format_stack(),\n"]], "error_stacktrace": ["Execution failed on sql 'SELECT DISTINCT vendor_id FROM mage.green_taxi': relation \"mage.green_taxi\" does not exist\nLINE 1: SELECT DISTINCT vendor_id FROM mage.green_taxi\n                                       ^\n"]}
Traceback (most recent call last):
  File "/usr/local/lib/python3.10/site-packages/pandas/io/sql.py", line 2018, in execute
    cur.execute(*args, **kwargs)
psycopg2.errors.UndefinedTable: relation "mage.green_taxi" does not exist
LINE 1: SELECT DISTINCT vendor_id FROM mage.green_taxi
                                       ^


The above exception was the direct cause of the following exception:

Traceback (most recent call last):
  File "/usr/local/lib/python3.10/site-packages/mage_ai/data_preparation/executors/block_executor.py", line 613, in execute
    result = __execute_with_retry()
  File "/usr/local/lib/python3.10/site-packages/mage_ai/shared/retry.py", line 54, in retry_func
    raise e
  File "/usr/local/lib/python3.10/site-packages/mage_ai/shared/retry.py", line 38, in retry_func
    return func(*args, **kwargs)
  File "/usr/local/lib/python3.10/site-packages/mage_ai/data_preparation/executors/block_executor.py", line 588, in __execute_with_retry
    return self._execute(
  File "/usr/local/lib/python3.10/site-packages/mage_ai/data_preparation/executors/block_executor.py", line 1077, in _execute
    result = self.block.execute_sync(
  File "/usr/local/lib/python3.10/site-packages/mage_ai/data_preparation/models/block/__init__.py", line 1312, in execute_sync
    raise err
  File "/usr/local/lib/python3.10/site-packages/mage_ai/data_preparation/models/block/__init__.py", line 1221, in execute_sync
    output = self.execute_block(
  File "/usr/local/lib/python3.10/site-packages/mage_ai/data_preparation/models/block/__init__.py", line 1527, in execute_block
    outputs = self._execute_block(
  File "/usr/local/lib/python3.10/site-packages/mage_ai/data_preparation/models/block/sql/__init__.py", line 721, in _execute_block
    return execute_sql_code(
  File "/usr/local/lib/python3.10/site-packages/mage_ai/data_preparation/models/block/sql/__init__.py", line 457, in execute_sql_code
    return execute_raw_sql(
  File "/usr/local/lib/python3.10/site-packages/mage_ai/data_preparation/models/block/sql/__init__.py", line 694, in execute_raw_sql
    results = loader.execute_queries(
  File "/usr/local/lib/python3.10/site-packages/mage_ai/io/sql.py", line 152, in execute_queries
    result = self.fetch_query(
  File "/usr/local/lib/python3.10/site-packages/mage_ai/io/sql.py", line 167, in fetch_query
    return read_sql(query, self.conn)
  File "/usr/local/lib/python3.10/site-packages/pandas/io/sql.py", line 564, in read_sql
    return pandas_sql.read_query(
  File "/usr/local/lib/python3.10/site-packages/pandas/io/sql.py", line 2078, in read_query
    cursor = self.execute(*args)
  File "/usr/local/lib/python3.10/site-packages/pandas/io/sql.py", line 2030, in execute
    raise ex from exc
pandas.errors.DatabaseError: Execution failed on sql 'SELECT DISTINCT vendor_id FROM mage.green_taxi': relation "mage.green_taxi" does not exist
LINE 1: SELECT DISTINCT vendor_id FROM mage.green_taxi
                                       ^

2024-02-06T14:01:49 {"cpu": 0.1181640625, "cpu_total": 3, "cpu_usage": 0.039388020833333336, "memory": 1281.0, "memory_total": 4011.0, "memory_usage": 0.3193717277486911, "pipeline_run_id": 1, "pipeline_schedule_id": 1, "pipeline_uuid": "green_taxi_etl", "hostname": "96649ac3d4ab", "level": "INFO", "message": "Pipeline green_taxi_etl for run 1 in schedule 1 is alive.", "timestamp": 1707228109.085394, "uuid": "f9aa112918c34dbbbd77505126679799"}
